Workbook

Sheet READ ME
A1: Twin Visit Logger — Development Copy (Reference Workbook)
A3: This reference workbook demonstrates the Phase 2 upgraded structure.
A4: The LIVE system is the Google Sheets dev copy; run apps-script/Setup.gs there to build it natively.
A6: Sheets:
A7: • Data — main pipeline (one row per property). Data starts on row 2.
A8: • Cherry Opportunity Board — the 30-second action view (10 sections).
A9: • Dropdowns — reference lists behind every data-validation field.
A10: • Exception Queue — records needing review (incomplete / rule failures / duplicates).
A11: • Migration Log — how legacy fields map to the new structure.
A13: Pilot + test records: rows 2–20 on Data.
A14: Original workbook was NOT modified. This is a separate development copy.
A16: Color key: Red = error/overdue Orange = warning/incomplete/stalled Green = signed/complete

Sheet Cherry Opportunity Board
A1: CHERRY OPPORTUNITY BOARD — actionable opportunities only
A2: Updated live from Data. Sections sorted by contract-likelihood, overdue, nearest due date, recent engagement.
A4: 1. Contracts Possible This Week
A5: Address | B5: Seller | C5: Stage | D5: Next Action | E5: Owner | F5: Due | G5: Days Overdue | H5: Blocker | I5: Last Contact Result | J5: REI Link
A6: =IFERROR(QUERY(Data!A2:BZ1000,"select B,D,AQ,AF,AH,AG,AK,AI,AE,H where B is not null and (AQ='Verbal Agreement' or AQ='Contract Sent' or AQ='Active Negotiation') order by AY desc, AG limit 50",0),"— none —")
A14: 2. Visited — No Offer Decision
A15: Address | B15: Seller | C15: Stage | D15: Next Action | E15: Owner | F15: Due | G15: Days Overdue | H15: Blocker | I15: Last Contact Result | J15: REI Link
A16: =IFERROR(QUERY(Data!A2:BZ1000,"select B,D,AQ,AF,AH,AG,AK,AI,AE,H where B is not null and AQ='Visit Completed — Needs Review' order by AK desc, AG limit 50",0),"— none —")
A24: 3. Offer Sent — Follow-Up Due
A25: Address | B25: Seller | C25: Stage | D25: Next Action | E25: Owner | F25: Due | G25: Days Overdue | H25: Blocker | I25: Last Contact Result | J25: REI Link
A26: =IFERROR(QUERY(Data!A2:BZ1000,"select B,D,AQ,AF,AH,AG,AK,AI,AE,H where B is not null and AQ='Offer Sent' order by AK desc, AG limit 50",0),"— none —")
A34: 4. Stalled Deals
A35: Address | B35: Seller | C35: Stage | D35: Next Action | E35: Owner | F35: Due | G35: Days Overdue | H35: Blocker | I35: Last Contact Result | J35: REI Link
A36: =IFERROR(QUERY(Data!A2:BZ1000,"select B,D,AQ,AF,AH,AG,AK,AI,AE,H where B is not null and AL='Yes' order by AK desc, AY desc limit 50",0),"— none —")
A44: 5. Overdue Tasks
A45: Address | B45: Seller | C45: Stage | D45: Next Action | E45: Owner | F45: Due | G45: Days Overdue | H45: Blocker | I45: Last Contact Result | J45: REI Link
A46: =IFERROR(QUERY(Data!A2:BZ1000,"select B,D,AQ,AF,AH,AG,AK,AI,AE,H where B is not null and AK>0 order by AK desc limit 50",0),"— none —")
A54: 6. Negotiation Decisions
A55: Address | B55: Seller | C55: Stage | D55: Next Action | E55: Owner | F55: Due | G55: Days Overdue | H55: Blocker | I55: Last Contact Result | J55: REI Link
A56: =IFERROR(QUERY(Data!A2:BZ1000,"select B,D,AQ,AF,AH,AG,AK,AI,AE,H where B is not null and AQ='Active Negotiation' order by AY desc, AG limit 50",0),"— none —")
A64: 7. Contract Handoffs
A65: Address | B65: Seller | C65: Stage | D65: Next Action | E65: Owner | F65: Due | G65: Days Overdue | H65: Blocker | I65: Last Contact Result | J65: REI Link
A66: =IFERROR(QUERY(Data!A2:BZ1000,"select B,D,AQ,AF,AH,AG,AK,AI,AE,H where B is not null and (AQ='Contract Signed' and AV<>'JM Confirmed') order by AG limit 50",0),"— none —")
A74: 8. Gift Review
A75: Address | B75: Seller | C75: Stage | D75: Next Action | E75: Owner | F75: Due | G75: Days Overdue | H75: Blocker | I75: Last Contact Result | J75: REI Link
A76: =IFERROR(QUERY(Data!A2:BZ1000,"select B,D,AQ,AF,AH,AG,AK,AI,AE,H where B is not null and AM='Recommended' order by AG limit 50",0),"— none —")
A84: 9. Revival Opportunities
A85: Address | B85: Seller | C85: Stage | D85: Next Action | E85: Owner | F85: Due | G85: Days Overdue | H85: Blocker | I85: Last Contact Result | J85: REI Link
A86: =IFERROR(QUERY(Data!A2:BZ1000,"select B,D,AQ,AF,AH,AG,AK,AI,AE,H where B is not null and (AR='Lost' and AJ>=45) order by AJ desc limit 50",0),"— none —")
A94: 10. Exceptions Requiring Review
A95: Address | B95: Seller | C95: Stage | D95: Next Action | E95: Owner | F95: Due | G95: Days Overdue | H95: Blocker | I95: Last Contact Result | J95: REI Link
A96: =IFERROR(QUERY(Data!A2:BZ1000,"select B,D,AQ,AF,AH,AG,AK,AI,AE,H where B is not null and (BD='Exception' or BD='Incomplete') order by AQ limit 50",0),"— none —")
A105: QUICK FILTERS (live sheet): use the toolbar Filter Views 'My Tasks', 'Due Today', 'Overdue', 'Stalled', 'Needs Offer Decision', 'Offer Follow-Up', 'Negotiation Decision', 'Contracts Possible This Week', 'Gift Review', 'Exceptions' — created by Setup.gs.

Sheet Data
A1: Property ID | B1: Property Address | C1: Normalized Address | D1: Seller Name | E1: Phone | F1: Email | G1: Lead Source | H1: REI BlackBook Link | I1: Visit Date | J1: Visit Time | K1: Visit Status | L1: Assigned Visitor | M1: Visit Notes | N1: Property Condition | O1: Occupancy Status | P1: Photos Link | Q1: Video Link | R1: File Link | S1: Seller Motivation | T1: Seller Timeline | U1: Asking Price | V1: Price Expectation | W1: Seller Concerns | X1: Approved Offer Amount | Y1: Offer Status | Z1: Offer Prepared Date | AA1: Offer Sent Date | AB1: Offer Received Confirmation | AC1: Counteroffer Amount | AD1: Last Contact Date | AE1: Last Contact Result | AF1: Next Action | AG1: Next Action Due Date | AH1: Assigned Owner | AI1: Blocker | AJ1: Days Since Last Activity | AK1: Days Overdue | AL1: Stalled Status | AM1: Gift Status | AN1: Gift Recommendation Reason | AO1: Gift Approval Owner | AP1: Gift Sent Date | AQ1: Current Stage | AR1: Final Disposition | AS1: Closeout Reason | AT1: Contract Sent Date | AU1: Contract Signed Date | AV1: Transaction Handoff Status | AW1: Missing Required Fields | AX1: Duplicate Address Flag | AY1: Opportunity Priority | AZ1: Created Date | BA1: Last Updated Date | BB1: Updated By | BC1: Source | BD1: Data Quality Status | BE1: Exception Reason | BF1: REI Update Required | BG1: REI Update Completed
A2: TVL-0001 | B2: 2607 Gimelli Pl, Apt 115, San Jose, CA 95133 | C2: =IF($B2="","",TRIM(LOWER(SUBSTITUTE(SUBSTITUTE(SUBSTITUTE(SUBSTITUTE(SUBSTITUTE($B2,",",""),".","")," apt "," "),"#","")," unit "," ")))) | D2: Cyn Ku | E2: (510) 284-7867 | G2: PPL - Property Leads | I2: 46227 | K2: Scheduled | L2: Juan | M2: Cyn still interested in selling; 2nd property she wants to sell to us. | AF2: Conduct scheduled visit & log outcome | AG2: 46227 | AH2: Juan | AJ2: =IF($B2="","",IF(AND($AD2="",$BA2="",$I2=""),"",TODAY()-MAX($AD2,$BA2,$I2))) | AK2: =IF($B2="","",IF($AG2="","",IF(TODAY()>$AG2,TODAY()-$AG2,0))) | AL2: =IF($B2="","",IF(OR($AQ2="Lost / Closed Out",$AQ2="Long-Term Nurture",$AQ2="Contract Signed"),"No",IF(MAX($AD2,$BA2,$I2)=0,"No",IF(NETWORKDAYS(MAX($AD2,$BA2,$I2),TODAY())-1>=3,"Yes","No")))) | AQ2: Visit Scheduled | AW2: =IF(OR($B2="",$AQ2="Lost / Closed Out"),"",_xlfn.TEXTJOIN(", ",TRUE,IF($B2="","Property Address",""),IF($AQ2="","Current Stage",""),IF($AF2="","Next Action",""),IF($AG2="","Next Action Due Date",""),IF($AH2="","Assigned Owner",""),IF($H2="","REI BlackBook Link",""))) | AX2: =IF($C2="","",IF(COUNTIFS($C$2:$C$1000,$C2,$AQ$2:$AQ$1000,"<>Lost / Closed Out")>1,"Duplicate","")) | AY2: =IF($B2="","",IF($AQ2="Verbal Agreement",100,IF($AQ2="Contract Sent",95,IF($AQ2="Active Negotiation",85,IF($AQ2="Offer Sent",70,IF($AQ2="Offer Preparation",60,IF($AQ2="Visit Completed — Needs Review",50,IF($AQ2="Visit Scheduled",30,IF($AQ2="Long-Term Nurture",10,IF($AQ2="Contract Signed",5,0)))))))))+IF($AK2="",0,MIN($AK2,20))+IF($AL2="Yes",5,0)) | AZ2: 46227 | BA2: 46227 | BB2: Import | BC2: Import | BD2: =IF($B2="","",IF($BE2<>"","Exception",IF($AW2<>"","Incomplete","OK"))) | BE2: =IF($B2="","",_xlfn.TEXTJOIN(" | ",TRUE,IF(AND($K2="Completed",$M2=""),"Completed visit missing Visit Notes",""),IF(AND($K2="Completed",$S2=""),"Completed visit missing Seller Motivation (or add Exception note)",""),IF(AND($AQ2="Offer Sent",OR($X2="",$AA2="")),"Offer Sent needs Approved Offer Amount + Offer Sent Date",""),IF(AND($AQ2="Active Negotiation",OR($AE2="",$AF2="",$AH2="",$AG2="")),"Active Negotiation needs Last Contact Result + Next Action + Owner + Due Date",""),IF(AND($AQ2="Contract Sent",$AT2="",$R2=""),"Contract Sent needs Contract Sent Date or File Link",""),IF(AND($AQ2="Contract Signed",$AU2=""),"Contract Signed needs Contract Signed Date",""),IF(AND($AQ2="Long-Term Nurture",OR($AG2="",$AG2<=TODAY())),"Long-Term Nurture needs an exact FUTURE follow-up date",""),IF(AND($AQ2="Lost / Closed Out",OR($AR2="",$AS2="")),"Lost / Closed Out needs Final Disposition + Closeout Reason",""),IF(AND($AM2="Sent",$AO2=""),"Gift marked Sent without recorded approval",""),IF($AX2="Duplicate","Duplicate active record for this address",""))) | BF2: Yes
A3: TVL-0002 | B3: 1253 Edgewood Rd, Redwood City, CA 94062 | C3: =IF($B3="","",TRIM(LOWER(SUBSTITUTE(SUBSTITUTE(SUBSTITUTE(SUBSTITUTE(SUBSTITUTE($B3,",",""),".","")," apt "," "),"#","")," unit "," ")))) | D3: Steve Giorgi | E3: (650) 333-8189 | G3: PPL - Property Leads | I3: 46225 | K3: Scheduled | L3: Juan | M3: Appointment booked; note outcome after visit. | AF3: Conduct scheduled visit & log outcome | AG3: 46225 | AH3: Juan | AJ3: =IF($B3="","",IF(AND($AD3="",$BA3="",$I3=""),"",TODAY()-MAX($AD3,$BA3,$I3))) | AK3: =IF($B3="","",IF($AG3="","",IF(TODAY()>$AG3,TODAY()-$AG3,0))) | AL3: =IF($B3="","",IF(OR($AQ3="Lost / Closed Out",$AQ3="Long-Term Nurture",$AQ3="Contract Signed"),"No",IF(MAX($AD3,$BA3,$I3)=0,"No",IF(NETWORKDAYS(MAX($AD3,$BA3,$I3),TODAY())-1>=3,"Yes","No")))) | AQ3: Visit Scheduled | AW3: =IF(OR($B3="",$AQ3="Lost / Closed Out"),"",_xlfn.TEXTJOIN(", ",TRUE,IF($B3="","Property Address",""),IF($AQ3="","Current Stage",""),IF($AF3="","Next Action",""),IF($AG3="","Next Action Due Date",""),IF($AH3="","Assigned Owner",""),IF($H3="","REI BlackBook Link",""))) | AX3: =IF($C3="","",IF(COUNTIFS($C$2:$C$1000,$C3,$AQ$2:$AQ$1000,"<>Lost / Closed Out")>1,"Duplicate","")) | AY3: =IF($B3="","",IF($AQ3="Verbal Agreement",100,IF($AQ3="Contract Sent",95,IF($AQ3="Active Negotiation",85,IF($AQ3="Offer Sent",70,IF($AQ3="Offer Preparation",60,IF($AQ3="Visit Completed — Needs Review",50,IF($AQ3="Visit Scheduled",30,IF($AQ3="Long-Term Nurture",10,IF($AQ3="Contract Signed",5,0)))))))))+IF($AK3="",0,MIN($AK3,20))+IF($AL3="Yes",5,0)) | AZ3: 46225 | BA3: 46225 | BB3: Import | BC3: Import | BD3: =IF($B3="","",IF($BE3<>"","Exception",IF($AW3<>"","Incomplete","OK"))) | BE3: =IF($B3="","",_xlfn.TEXTJOIN(" | ",TRUE,IF(AND($K3="Completed",$M3=""),"Completed visit missing Visit Notes",""),IF(AND($K3="Completed",$S3=""),"Completed visit missing Seller Motivation (or add Exception note)",""),IF(AND($AQ3="Offer Sent",OR($X3="",$AA3="")),"Offer Sent needs Approved Offer Amount + Offer Sent Date",""),IF(AND($AQ3="Active Negotiation",OR($AE3="",$AF3="",$AH3="",$AG3="")),"Active Negotiation needs Last Contact Result + Next Action + Owner + Due Date",""),IF(AND($AQ3="Contract Sent",$AT3="",$R3=""),"Contract Sent needs Contract Sent Date or File Link",""),IF(AND($AQ3="Contract Signed",$AU3=""),"Contract Signed needs Contract Signed Date",""),IF(AND($AQ3="Long-Term Nurture",OR($AG3="",$AG3<=TODAY())),"Long-Term Nurture needs an exact FUTURE follow-up date",""),IF(AND($AQ3="Lost / Closed Out",OR($AR3="",$AS3="")),"Lost / Closed Out needs Final Disposition + Closeout Reason",""),IF(AND($AM3="Sent",$AO3=""),"Gift marked Sent without recorded approval",""),IF($AX3="Duplicate","Duplicate active record for this address",""))) | BF3: Yes
A4: TVL-0003 | B4: 519 S 17th St, Richmond, CA 94804 | C4: =IF($B4="","",TRIM(LOWER(SUBSTITUTE(SUBSTITUTE(SUBSTITUTE(SUBSTITUTE(SUBSTITUTE($B4,",",""),".","")," apt "," "),"#","")," unit "," ")))) | D4: Carmen Green | E4: (916) 752-5759 | G4: PPL - Motivated Leads | I4: 46223 | K4: Completed | L4: Juan | M4: Offer sent via email + SignNow contract; Juan following up directly. | S4: Interested in selling (motivation detail not captured in legacy) | Y4: Sent | AD4: 46223 | AE4: Offer emailed; awaiting seller response | AF4: Follow up on sent offer | AG4: 46226 | AH4: Juan | AJ4: =IF($B4="","",IF(AND($AD4="",$BA4="",$I4=""),"",TODAY()-MAX($AD4,$BA4,$I4))) | AK4: =IF($B4="","",IF($AG4="","",IF(TODAY()>$AG4,TODAY()-$AG4,0))) | AL4: =IF($B4="","",IF(OR($AQ4="Lost / Closed Out",$AQ4="Long-Term Nurture",$AQ4="Contract Signed"),"No",IF(MAX($AD4,$BA4,$I4)=0,"No",IF(NETWORKDAYS(MAX($AD4,$BA4,$I4),TODAY())-1>=3,"Yes","No")))) | AQ4: Offer Sent | AW4: =IF(OR($B4="",$AQ4="Lost / Closed Out"),"",_xlfn.TEXTJOIN(", ",TRUE,IF($B4="","Property Address",""),IF($AQ4="","Current Stage",""),IF($AF4="","Next Action",""),IF($AG4="","Next Action Due Date",""),IF($AH4="","Assigned Owner",""),IF($H4="","REI BlackBook Link",""))) | AX4: =IF($C4="","",IF(COUNTIFS($C$2:$C$1000,$C4,$AQ$2:$AQ$1000,"<>Lost / Closed Out")>1,"Duplicate","")) | AY4: =IF($B4="","",IF($AQ4="Verbal Agreement",100,IF($AQ4="Contract Sent",95,IF($AQ4="Active Negotiation",85,IF($AQ4="Offer Sent",70,IF($AQ4="Offer Preparation",60,IF($AQ4="Visit Completed — Needs Review",50,IF($AQ4="Visit Scheduled",30,IF($AQ4="Long-Term Nurture",10,IF($AQ4="Contract Signed",5,0)))))))))+IF($AK4="",0,MIN($AK4,20))+IF($AL4="Yes",5,0)) | AZ4: 46223 | BA4: 46223 | BB4: Import | BC4: Import | BD4: =IF($B4="","",IF($BE4<>"","Exception",IF($AW4<>"","Incomplete","OK"))) | BE4: =IF($B4="","",_xlfn.TEXTJOIN(" | ",TRUE,IF(AND($K4="Completed",$M4=""),"Completed visit missing Visit Notes",""),IF(AND($K4="Completed",$S4=""),"Completed visit missing Seller Motivation (or add Exception note)",""),IF(AND($AQ4="Offer Sent",OR($X4="",$AA4="")),"Offer Sent needs Approved Offer Amount + Offer Sent Date",""),IF(AND($AQ4="Active Negotiation",OR($AE4="",$AF4="",$AH4="",$AG4="")),"Active Negotiation needs Last Contact Result + Next Action + Owner + Due Date",""),IF(AND($AQ4="Contract Sent",$AT4="",$R4=""),"Contract Sent needs Contract Sent Date or File Link",""),IF(AND($AQ4="Contract Signed",$AU4=""),"Contract Signed needs Contract Signed Date",""),IF(AND($AQ4="Long-Term Nurture",OR($AG4="",$AG4<=TODAY())),"Long-Term Nurture needs an exact FUTURE follow-up date",""),IF(AND($AQ4="Lost / Closed Out",OR($AR4="",$AS4="")),"Lost / Closed Out needs Final Disposition + Closeout Reason",""),IF(AND($AM4="Sent",$AO4=""),"Gift marked Sent without recorded approval",""),IF($AX4="Duplicate","Duplicate active record for this address",""))) | BF4: Yes
A5: TVL-0004 | B5: 5 Lancaster Cir Apt 121, Bay Point, CA 94565 | C5: =IF($B5="","",TRIM(LOWER(SUBSTITUTE(SUBSTITUTE(SUBSTITUTE(SUBSTITUTE(SUBSTITUTE($B5,",",""),".","")," apt "," "),"#","")," unit "," ")))) | D5: Dorol Conrad | E5: (415) 370-9841 | G5: PPL - Property Leads | I5: 46223 | K5: Canceled | M5: Equity 100% but property already listed on the MLS. | AJ5: =IF($B5="","",IF(AND($AD5="",$BA5="",$I5=""),"",TODAY()-MAX($AD5,$BA5,$I5))) | AK5: =IF($B5="","",IF($AG5="","",IF(TODAY()>$AG5,TODAY()-$AG5,0))) | AL5: =IF($B5="","",IF(OR($AQ5="Lost / Closed Out",$AQ5="Long-Term Nurture",$AQ5="Contract Signed"),"No",IF(MAX($AD5,$BA5,$I5)=0,"No",IF(NETWORKDAYS(MAX($AD5,$BA5,$I5),TODAY())-1>=3,"Yes","No")))) | AQ5: Lost / Closed Out | AR5: Lost | AS5: We're Passing — already listed on MLS | AW5: =IF(OR($B5="",$AQ5="Lost / Closed Out"),"",_xlfn.TEXTJOIN(", ",TRUE,IF($B5="","Property Address",""),IF($AQ5="","Current Stage",""),IF($AF5="","Next Action",""),IF($AG5="","Next Action Due Date",""),IF($AH5="","Assigned Owner",""),IF($H5="","REI BlackBook Link",""))) | AX5: =IF($C5="","",IF(COUNTIFS($C$2:$C$1000,$C5,$AQ$2:$AQ$1000,"<>Lost / Closed Out")>1,"Duplicate","")) | AY5: =IF($B5="","",IF($AQ5="Verbal Agreement",100,IF($AQ5="Contract Sent",95,IF($AQ5="Active Negotiation",85,IF($AQ5="Offer Sent",70,IF($AQ5="Offer Preparation",60,IF($AQ5="Visit Completed — Needs Review",50,IF($AQ5="Visit Scheduled",30,IF($AQ5="Long-Term Nurture",10,IF($AQ5="Contract Signed",5,0)))))))))+IF($AK5="",0,MIN($AK5,20))+IF($AL5="Yes",5,0)) | AZ5: 46223 | BA5: 46223 | BB5: Import | BC5: Import | BD5: =IF($B5="","",IF($BE5<>"","Exception",IF($AW5<>"","Incomplete","OK"))) | BE5: =IF($B5="","",_xlfn.TEXTJOIN(" | ",TRUE,IF(AND($K5="Completed",$M5=""),"Completed visit missing Visit Notes",""),IF(AND($K5="Completed",$S5=""),"Completed visit missing Seller Motivation (or add Exception note)",""),IF(AND($AQ5="Offer Sent",OR($X5="",$AA5="")),"Offer Sent needs Approved Offer Amount + Offer Sent Date",""),IF(AND($AQ5="Active Negotiation",OR($AE5="",$AF5="",$AH5="",$AG5="")),"Active Negotiation needs Last Contact Result + Next Action + Owner + Due Date",""),IF(AND($AQ5="Contract Sent",$AT5="",$R5=""),"Contract Sent needs Contract Sent Date or File Link",""),IF(AND($AQ5="Contract Signed",$AU5=""),"Contract Signed needs Contract Signed Date",""),IF(AND($AQ5="Long-Term Nurture",OR($AG5="",$AG5<=TODAY())),"Long-Term Nurture needs an exact FUTURE follow-up date",""),IF(AND($AQ5="Lost / Closed Out",OR($AR5="",$AS5="")),"Lost / Closed Out needs Final Disposition + Closeout Reason",""),IF(AND($AM5="Sent",$AO5=""),"Gift marked Sent without recorded approval",""),IF($AX5="Duplicate","Duplicate active record for this address","")))
A6: TVL-0005 | B6: 15340 Canyon 2 Rd, Guerneville, CA 95446 | C6: =IF($B6="","",TRIM(LOWER(SUBSTITUTE(SUBSTITUTE(SUBSTITUTE(SUBSTITUTE(SUBSTITUTE($B6,",",""),".","")," apt "," "),"#","")," unit "," ")))) | D6: Jon Box | E6: (707) 481-7040 | G6: PPL - Property Leads | I6: 46223 | K6: Canceled | L6: Juan | M6: Passing on this lead. | AJ6: =IF($B6="","",IF(AND($AD6="",$BA6="",$I6=""),"",TODAY()-MAX($AD6,$BA6,$I6))) | AK6: =IF($B6="","",IF($AG6="","",IF(TODAY()>$AG6,TODAY()-$AG6,0))) | AL6: =IF($B6="","",IF(OR($AQ6="Lost / Closed Out",$AQ6="Long-Term Nurture",$AQ6="Contract Signed"),"No",IF(MAX($AD6,$BA6,$I6)=0,"No",IF(NETWORKDAYS(MAX($AD6,$BA6,$I6),TODAY())-1>=3,"Yes","No")))) | AQ6: Lost / Closed Out | AR6: Lost | AS6: We're Passing | AW6: =IF(OR($B6="",$AQ6="Lost / Closed Out"),"",_xlfn.TEXTJOIN(", ",TRUE,IF($B6="","Property Address",""),IF($AQ6="","Current Stage",""),IF($AF6="","Next Action",""),IF($AG6="","Next Action Due Date",""),IF($AH6="","Assigned Owner",""),IF($H6="","REI BlackBook Link",""))) | AX6: =IF($C6="","",IF(COUNTIFS($C$2:$C$1000,$C6,$AQ$2:$AQ$1000,"<>Lost / Closed Out")>1,"Duplicate","")) | AY6: =IF($B6="","",IF($AQ6="Verbal Agreement",100,IF($AQ6="Contract Sent",95,IF($AQ6="Active Negotiation",85,IF($AQ6="Offer Sent",70,IF($AQ6="Offer Preparation",60,IF($AQ6="Visit Completed — Needs Review",50,IF($AQ6="Visit Scheduled",30,IF($AQ6="Long-Term Nurture",10,IF($AQ6="Contract Signed",5,0)))))))))+IF($AK6="",0,MIN($AK6,20))+IF($AL6="Yes",5,0)) | AZ6: 46221 | BA6: 46221 | BB6: Import | BC6: Import | BD6: =IF($B6="","",IF($BE6<>"","Exception",IF($AW6<>"","Incomplete","OK"))) | BE6: =IF($B6="","",_xlfn.TEXTJOIN(" | ",TRUE,IF(AND($K6="Completed",$M6=""),"Completed visit missing Visit Notes",""),IF(AND($K6="Completed",$S6=""),"Completed visit missing Seller Motivation (or add Exception note)",""),IF(AND($AQ6="Offer Sent",OR($X6="",$AA6="")),"Offer Sent needs Approved Offer Amount + Offer Sent Date",""),IF(AND($AQ6="Active Negotiation",OR($AE6="",$AF6="",$AH6="",$AG6="")),"Active Negotiation needs Last Contact Result + Next Action + Owner + Due Date",""),IF(AND($AQ6="Contract Sent",$AT6="",$R6=""),"Contract Sent needs Contract Sent Date or File Link",""),IF(AND($AQ6="Contract Signed",$AU6=""),"Contract Signed needs Contract Signed Date",""),IF(AND($AQ6="Long-Term Nurture",OR($AG6="",$AG6<=TODAY())),"Long-Term Nurture needs an exact FUTURE follow-up date",""),IF(AND($AQ6="Lost / Closed Out",OR($AR6="",$AS6="")),"Lost / Closed Out needs Final Disposition + Closeout Reason",""),IF(AND($AM6="Sent",$AO6=""),"Gift marked Sent without recorded approval",""),IF($AX6="Duplicate","Duplicate active record for this address","")))
A7: TVL-0006 | B7: 18 Hampton Rd, Occidental, CA 95465 | C7: =IF($B7="","",TRIM(LOWER(SUBSTITUTE(SUBSTITUTE(SUBSTITUTE(SUBSTITUTE(SUBSTITUTE($B7,",",""),".","")," apt "," "),"#","")," unit "," ")))) | D7: Chris J. Giro | E7: (707) 292-9001 | G7: PPC | I7: 46221 | K7: Completed | L7: Juan | M7: House is structurally failing; passing. | S7: Motivated but property condition too poor for our criteria | AJ7: =IF($B7="","",IF(AND($AD7="",$BA7="",$I7=""),"",TODAY()-MAX($AD7,$BA7,$I7))) | AK7: =IF($B7="","",IF($AG7="","",IF(TODAY()>$AG7,TODAY()-$AG7,0))) | AL7: =IF($B7="","",IF(OR($AQ7="Lost / Closed Out",$AQ7="Long-Term Nurture",$AQ7="Contract Signed"),"No",IF(MAX($AD7,$BA7,$I7)=0,"No",IF(NETWORKDAYS(MAX($AD7,$BA7,$I7),TODAY())-1>=3,"Yes","No")))) | AQ7: Lost / Closed Out | AR7: Lost | AS7: We're Passing — structural condition | AW7: =IF(OR($B7="",$AQ7="Lost / Closed Out"),"",_xlfn.TEXTJOIN(", ",TRUE,IF($B7="","Property Address",""),IF($AQ7="","Current Stage",""),IF($AF7="","Next Action",""),IF($AG7="","Next Action Due Date",""),IF($AH7="","Assigned Owner",""),IF($H7="","REI BlackBook Link",""))) | AX7: =IF($C7="","",IF(COUNTIFS($C$2:$C$1000,$C7,$AQ$2:$AQ$1000,"<>Lost / Closed Out")>1,"Duplicate","")) | AY7: =IF($B7="","",IF($AQ7="Verbal Agreement",100,IF($AQ7="Contract Sent",95,IF($AQ7="Active Negotiation",85,IF($AQ7="Offer Sent",70,IF($AQ7="Offer Preparation",60,IF($AQ7="Visit Completed — Needs Review",50,IF($AQ7="Visit Scheduled",30,IF($AQ7="Long-Term Nurture",10,IF($AQ7="Contract Signed",5,0)))))))))+IF($AK7="",0,MIN($AK7,20))+IF($AL7="Yes",5,0)) | AZ7: 46219 | BA7: 46221 | BB7: Import | BC7: Import | BD7: =IF($B7="","",IF($BE7<>"","Exception",IF($AW7<>"","Incomplete","OK"))) | BE7: =IF($B7="","",_xlfn.TEXTJOIN(" | ",TRUE,IF(AND($K7="Completed",$M7=""),"Completed visit missing Visit Notes",""),IF(AND($K7="Completed",$S7=""),"Completed visit missing Seller Motivation (or add Exception note)",""),IF(AND($AQ7="Offer Sent",OR($X7="",$AA7="")),"Offer Sent needs Approved Offer Amount + Offer Sent Date",""),IF(AND($AQ7="Active Negotiation",OR($AE7="",$AF7="",$AH7="",$AG7="")),"Active Negotiation needs Last Contact Result + Next Action + Owner + Due Date",""),IF(AND($AQ7="Contract Sent",$AT7="",$R7=""),"Contract Sent needs Contract Sent Date or File Link",""),IF(AND($AQ7="Contract Signed",$AU7=""),"Contract Signed needs Contract Signed Date",""),IF(AND($AQ7="Long-Term Nurture",OR($AG7="",$AG7<=TODAY())),"Long-Term Nurture needs an exact FUTURE follow-up date",""),IF(AND($AQ7="Lost / Closed Out",OR($AR7="",$AS7="")),"Lost / Closed Out needs Final Disposition + Closeout Reason",""),IF(AND($AM7="Sent",$AO7=""),"Gift marked Sent without recorded approval",""),IF($AX7="Duplicate","Duplicate active record for this address","")))
A8: TVL-0007 | B8: 4107 Randolph Ave, Oakland, CA 94602 | C8: =IF($B8="","",TRIM(LOWER(SUBSTITUTE(SUBSTITUTE(SUBSTITUTE(SUBSTITUTE(SUBSTITUTE($B8,",",""),".","")," apt "," "),"#","")," unit "," ")))) | D8: Yvette D Rose | E8: (510) 457-6727 | G8: TV | I8: 46221 | K8: Completed | M8: Heavily tenant-occupied; City of Oakland code violations. | O8: Tenant-Occupied | S8: Good location but tenant/code issues; passing | AI8: Tenant | AJ8: =IF($B8="","",IF(AND($AD8="",$BA8="",$I8=""),"",TODAY()-MAX($AD8,$BA8,$I8))) | AK8: =IF($B8="","",IF($AG8="","",IF(TODAY()>$AG8,TODAY()-$AG8,0))) | AL8: =IF($B8="","",IF(OR($AQ8="Lost / Closed Out",$AQ8="Long-Term Nurture",$AQ8="Contract Signed"),"No",IF(MAX($AD8,$BA8,$I8)=0,"No",IF(NETWORKDAYS(MAX($AD8,$BA8,$I8),TODAY())-1>=3,"Yes","No")))) | AQ8: Lost / Closed Out | AR8: Lost | AS8: We're Passing — tenant-occupied + code violations | AW8: =IF(OR($B8="",$AQ8="Lost / Closed Out"),"",_xlfn.TEXTJOIN(", ",TRUE,IF($B8="","Property Address",""),IF($AQ8="","Current Stage",""),IF($AF8="","Next Action",""),IF($AG8="","Next Action Due Date",""),IF($AH8="","Assigned Owner",""),IF($H8="","REI BlackBook Link",""))) | AX8: =IF($C8="","",IF(COUNTIFS($C$2:$C$1000,$C8,$AQ$2:$AQ$1000,"<>Lost / Closed Out")>1,"Duplicate","")) | AY8: =IF($B8="","",IF($AQ8="Verbal Agreement",100,IF($AQ8="Contract Sent",95,IF($AQ8="Active Negotiation",85,IF($AQ8="Offer Sent",70,IF($AQ8="Offer Preparation",60,IF($AQ8="Visit Completed — Needs Review",50,IF($AQ8="Visit Scheduled",30,IF($AQ8="Long-Term Nurture",10,IF($AQ8="Contract Signed",5,0)))))))))+IF($AK8="",0,MIN($AK8,20))+IF($AL8="Yes",5,0)) | AZ8: 46219 | BA8: 46220 | BB8: Import | BC8: Import | BD8: =IF($B8="","",IF($BE8<>"","Exception",IF($AW8<>"","Incomplete","OK"))) | BE8: =IF($B8="","",_xlfn.TEXTJOIN(" | ",TRUE,IF(AND($K8="Completed",$M8=""),"Completed visit missing Visit Notes",""),IF(AND($K8="Completed",$S8=""),"Completed visit missing Seller Motivation (or add Exception note)",""),IF(AND($AQ8="Offer Sent",OR($X8="",$AA8="")),"Offer Sent needs Approved Offer Amount + Offer Sent Date",""),IF(AND($AQ8="Active Negotiation",OR($AE8="",$AF8="",$AH8="",$AG8="")),"Active Negotiation needs Last Contact Result + Next Action + Owner + Due Date",""),IF(AND($AQ8="Contract Sent",$AT8="",$R8=""),"Contract Sent needs Contract Sent Date or File Link",""),IF(AND($AQ8="Contract Signed",$AU8=""),"Contract Signed needs Contract Signed Date",""),IF(AND($AQ8="Long-Term Nurture",OR($AG8="",$AG8<=TODAY())),"Long-Term Nurture needs an exact FUTURE follow-up date",""),IF(AND($AQ8="Lost / Closed Out",OR($AR8="",$AS8="")),"Lost / Closed Out needs Final Disposition + Closeout Reason",""),IF(AND($AM8="Sent",$AO8=""),"Gift marked Sent without recorded approval",""),IF($AX8="Duplicate","Duplicate active record for this address","")))
A9: TVL-0008 | B9: 16125 Bittner Rd, Occidental, CA 95465 | C9: =IF($B9="","",TRIM(LOWER(SUBSTITUTE(SUBSTITUTE(SUBSTITUTE(SUBSTITUTE(SUBSTITUTE($B9,",",""),".","")," apt "," "),"#","")," unit "," ")))) | D9: Liam | E9: (530) 545-1943 | G9: PPL - Property Leads | I9: 46218 | K9: Canceled | M9: Internal cancellation of confirmed visit; passing. | AJ9: =IF($B9="","",IF(AND($AD9="",$BA9="",$I9=""),"",TODAY()-MAX($AD9,$BA9,$I9))) | AK9: =IF($B9="","",IF($AG9="","",IF(TODAY()>$AG9,TODAY()-$AG9,0))) | AL9: =IF($B9="","",IF(OR($AQ9="Lost / Closed Out",$AQ9="Long-Term Nurture",$AQ9="Contract Signed"),"No",IF(MAX($AD9,$BA9,$I9)=0,"No",IF(NETWORKDAYS(MAX($AD9,$BA9,$I9),TODAY())-1>=3,"Yes","No")))) | AQ9: Lost / Closed Out | AR9: Lost | AS9: We're Passing — internal cancellation | AW9: =IF(OR($B9="",$AQ9="Lost / Closed Out"),"",_xlfn.TEXTJOIN(", ",TRUE,IF($B9="","Property Address",""),IF($AQ9="","Current Stage",""),IF($AF9="","Next Action",""),IF($AG9="","Next Action Due Date",""),IF($AH9="","Assigned Owner",""),IF($H9="","REI BlackBook Link",""))) | AX9: =IF($C9="","",IF(COUNTIFS($C$2:$C$1000,$C9,$AQ$2:$AQ$1000,"<>Lost / Closed Out")>1,"Duplicate","")) | AY9: =IF($B9="","",IF($AQ9="Verbal Agreement",100,IF($AQ9="Contract Sent",95,IF($AQ9="Active Negotiation",85,IF($AQ9="Offer Sent",70,IF($AQ9="Offer Preparation",60,IF($AQ9="Visit Completed — Needs Review",50,IF($AQ9="Visit Scheduled",30,IF($AQ9="Long-Term Nurture",10,IF($AQ9="Contract Signed",5,0)))))))))+IF($AK9="",0,MIN($AK9,20))+IF($AL9="Yes",5,0)) | AZ9: 46218 | BA9: 46218 | BB9: Import | BC9: Import | BD9: =IF($B9="","",IF($BE9<>"","Exception",IF($AW9<>"","Incomplete","OK"))) | BE9: =IF($B9="","",_xlfn.TEXTJOIN(" | ",TRUE,IF(AND($K9="Completed",$M9=""),"Completed visit missing Visit Notes",""),IF(AND($K9="Completed",$S9=""),"Completed visit missing Seller Motivation (or add Exception note)",""),IF(AND($AQ9="Offer Sent",OR($X9="",$AA9="")),"Offer Sent needs Approved Offer Amount + Offer Sent Date",""),IF(AND($AQ9="Active Negotiation",OR($AE9="",$AF9="",$AH9="",$AG9="")),"Active Negotiation needs Last Contact Result + Next Action + Owner + Due Date",""),IF(AND($AQ9="Contract Sent",$AT9="",$R9=""),"Contract Sent needs Contract Sent Date or File Link",""),IF(AND($AQ9="Contract Signed",$AU9=""),"Contract Signed needs Contract Signed Date",""),IF(AND($AQ9="Long-Term Nurture",OR($AG9="",$AG9<=TODAY())),"Long-Term Nurture needs an exact FUTURE follow-up date",""),IF(AND($AQ9="Lost / Closed Out",OR($AR9="",$AS9="")),"Lost / Closed Out needs Final Disposition + Closeout Reason",""),IF(AND($AM9="Sent",$AO9=""),"Gift marked Sent without recorded approval",""),IF($AX9="Duplicate","Duplicate active record for this address","")))
A10: TVL-0009 | B10: 39224 Guardino Dr Apt 208, Fremont, CA 94538 | C10: =IF($B10="","",TRIM(LOWER(SUBSTITUTE(SUBSTITUTE(SUBSTITUTE(SUBSTITUTE(SUBSTITUTE($B10,",",""),".","")," apt "," "),"#","")," unit "," ")))) | D10: James White | E10: (209) 221-1240 | G10: PPL - Property Leads | I10: 46217 | K10: Completed | L10: Cesar | M10: Offer emailed; James (trustee) + sister Lisa reviewing together. Cherry following up. | S10: Trustee sale; reviewing offer with family | Y10: Sent | AD10: 46218 | AE10: Cherry emailing offer breakdown; family reviewing | AF10: Follow up on offer with James/Lisa | AG10: 46220 | AH10: Cherry | AI10: Family | AJ10: =IF($B10="","",IF(AND($AD10="",$BA10="",$I10=""),"",TODAY()-MAX($AD10,$BA10,$I10))) | AK10: =IF($B10="","",IF($AG10="","",IF(TODAY()>$AG10,TODAY()-$AG10,0))) | AL10: =IF($B10="","",IF(OR($AQ10="Lost / Closed Out",$AQ10="Long-Term Nurture",$AQ10="Contract Signed"),"No",IF(MAX($AD10,$BA10,$I10)=0,"No",IF(NETWORKDAYS(MAX($AD10,$BA10,$I10),TODAY())-1>=3,"Yes","No")))) | AQ10: Offer Sent | AW10: =IF(OR($B10="",$AQ10="Lost / Closed Out"),"",_xlfn.TEXTJOIN(", ",TRUE,IF($B10="","Property Address",""),IF($AQ10="","Current Stage",""),IF($AF10="","Next Action",""),IF($AG10="","Next Action Due Date",""),IF($AH10="","Assigned Owner",""),IF($H10="","REI BlackBook Link",""))) | AX10: =IF($C10="","",IF(COUNTIFS($C$2:$C$1000,$C10,$AQ$2:$AQ$1000,"<>Lost / Closed Out")>1,"Duplicate","")) | AY10: =IF($B10="","",IF($AQ10="Verbal Agreement",100,IF($AQ10="Contract Sent",95,IF($AQ10="Active Negotiation",85,IF($AQ10="Offer Sent",70,IF($AQ10="Offer Preparation",60,IF($AQ10="Visit Completed — Needs Review",50,IF($AQ10="Visit Scheduled",30,IF($AQ10="Long-Term Nurture",10,IF($AQ10="Contract Signed",5,0)))))))))+IF($AK10="",0,MIN($AK10,20))+IF($AL10="Yes",5,0)) | AZ10: 46217 | BA10: 46218 | BB10: Import | BC10: Import | BD10: =IF($B10="","",IF($BE10<>"","Exception",IF($AW10<>"","Incomplete","OK"))) | BE10: =IF($B10="","",_xlfn.TEXTJOIN(" | ",TRUE,IF(AND($K10="Completed",$M10=""),"Completed visit missing Visit Notes",""),IF(AND($K10="Completed",$S10=""),"Completed visit missing Seller Motivation (or add Exception note)",""),IF(AND($AQ10="Offer Sent",OR($X10="",$AA10="")),"Offer Sent needs Approved Offer Amount + Offer Sent Date",""),IF(AND($AQ10="Active Negotiation",OR($AE10="",$AF10="",$AH10="",$AG10="")),"Active Negotiation needs Last Contact Result + Next Action + Owner + Due Date",""),IF(AND($AQ10="Contract Sent",$AT10="",$R10=""),"Contract Sent needs Contract Sent Date or File Link",""),IF(AND($AQ10="Contract Signed",$AU10=""),"Contract Signed needs Contract Signed Date",""),IF(AND($AQ10="Long-Term Nurture",OR($AG10="",$AG10<=TODAY())),"Long-Term Nurture needs an exact FUTURE follow-up date",""),IF(AND($AQ10="Lost / Closed Out",OR($AR10="",$AS10="")),"Lost / Closed Out needs Final Disposition + Closeout Reason",""),IF(AND($AM10="Sent",$AO10=""),"Gift marked Sent without recorded approval",""),IF($AX10="Duplicate","Duplicate active record for this address",""))) | BF10: Yes
A11: TVL-0010 | B11: 1323 Oxford St, Berkeley, CA 94709 | C11: =IF($B11="","",TRIM(LOWER(SUBSTITUTE(SUBSTITUTE(SUBSTITUTE(SUBSTITUTE(SUBSTITUTE($B11,",",""),".","")," apt "," "),"#","")," unit "," ")))) | D11: Mark Lempert | E11: (510) 816-1221 | G11: Direct Mail - Postcard | I11: 46216 | K11: Completed | L11: Cesar | M11: SERVICE FAILURE: walkthrough done 7/13 but no offer ever sent; seller displeased. | S11: Was open to offer; lost due to our delay/no-offer | AI11: Documents | AJ11: =IF($B11="","",IF(AND($AD11="",$BA11="",$I11=""),"",TODAY()-MAX($AD11,$BA11,$I11))) | AK11: =IF($B11="","",IF($AG11="","",IF(TODAY()>$AG11,TODAY()-$AG11,0))) | AL11: =IF($B11="","",IF(OR($AQ11="Lost / Closed Out",$AQ11="Long-Term Nurture",$AQ11="Contract Signed"),"No",IF(MAX($AD11,$BA11,$I11)=0,"No",IF(NETWORKDAYS(MAX($AD11,$BA11,$I11),TODAY())-1>=3,"Yes","No")))) | AQ11: Lost / Closed Out | AR11: Lost | AS11: Did Not Proceed — service failure (no offer sent) | AW11: =IF(OR($B11="",$AQ11="Lost / Closed Out"),"",_xlfn.TEXTJOIN(", ",TRUE,IF($B11="","Property Address",""),IF($AQ11="","Current Stage",""),IF($AF11="","Next Action",""),IF($AG11="","Next Action Due Date",""),IF($AH11="","Assigned Owner",""),IF($H11="","REI BlackBook Link",""))) | AX11: =IF($C11="","",IF(COUNTIFS($C$2:$C$1000,$C11,$AQ$2:$AQ$1000,"<>Lost / Closed Out")>1,"Duplicate","")) | AY11: =IF($B11="","",IF($AQ11="Verbal Agreement",100,IF($AQ11="Contract Sent",95,IF($AQ11="Active Negotiation",85,IF($AQ11="Offer Sent",70,IF($AQ11="Offer Preparation",60,IF($AQ11="Visit Completed — Needs Review",50,IF($AQ11="Visit Scheduled",30,IF($AQ11="Long-Term Nurture",10,IF($AQ11="Contract Signed",5,0)))))))))+IF($AK11="",0,MIN($AK11,20))+IF($AL11="Yes",5,0)) | AZ11: 46216 | BA11: 46218 | BB11: Import | BC11: Import | BD11: =IF($B11="","",IF($BE11<>"","Exception",IF($AW11<>"","Incomplete","OK"))) | BE11: =IF($B11="","",_xlfn.TEXTJOIN(" | ",TRUE,IF(AND($K11="Completed",$M11=""),"Completed visit missing Visit Notes",""),IF(AND($K11="Completed",$S11=""),"Completed visit missing Seller Motivation (or add Exception note)",""),IF(AND($AQ11="Offer Sent",OR($X11="",$AA11="")),"Offer Sent needs Approved Offer Amount + Offer Sent Date",""),IF(AND($AQ11="Active Negotiation",OR($AE11="",$AF11="",$AH11="",$AG11="")),"Active Negotiation needs Last Contact Result + Next Action + Owner + Due Date",""),IF(AND($AQ11="Contract Sent",$AT11="",$R11=""),"Contract Sent needs Contract Sent Date or File Link",""),IF(AND($AQ11="Contract Signed",$AU11=""),"Contract Signed needs Contract Signed Date",""),IF(AND($AQ11="Long-Term Nurture",OR($AG11="",$AG11<=TODAY())),"Long-Term Nurture needs an exact FUTURE follow-up date",""),IF(AND($AQ11="Lost / Closed Out",OR($AR11="",$AS11="")),"Lost / Closed Out needs Final Disposition + Closeout Reason",""),IF(AND($AM11="Sent",$AO11=""),"Gift marked Sent without recorded approval",""),IF($AX11="Duplicate","Duplicate active record for this address","")))
A12: TEST-01 | B12: 100 Test Verbal Ln, Testville, CA 90001 | C12: =IF($B12="","",TRIM(LOWER(SUBSTITUTE(SUBSTITUTE(SUBSTITUTE(SUBSTITUTE(SUBSTITUTE($B12,",",""),".","")," apt "," "),"#","")," unit "," ")))) | D12: Val Verbal | E12: (000) 000-0001 | G12: PPC | H12: https://app.reiblackbook.com/lead/test01 | I12: 46221 | K12: Completed | L12: Juan | M12: Great condition; seller keen. | S12: Relocating for job — motivated | X12: 640000 | Y12: Accepted | AA12: 46222 | AD12: 46224 | AE12: Seller verbally agreed to $640k | AF12: Prepare purchase contract | AG12: 46226 | AH12: Kyle | AJ12: =IF($B12="","",IF(AND($AD12="",$BA12="",$I12=""),"",TODAY()-MAX($AD12,$BA12,$I12))) | AK12: =IF($B12="","",IF($AG12="","",IF(TODAY()>$AG12,TODAY()-$AG12,0))) | AL12: =IF($B12="","",IF(OR($AQ12="Lost / Closed Out",$AQ12="Long-Term Nurture",$AQ12="Contract Signed"),"No",IF(MAX($AD12,$BA12,$I12)=0,"No",IF(NETWORKDAYS(MAX($AD12,$BA12,$I12),TODAY())-1>=3,"Yes","No")))) | AQ12: Verbal Agreement | AW12: =IF(OR($B12="",$AQ12="Lost / Closed Out"),"",_xlfn.TEXTJOIN(", ",TRUE,IF($B12="","Property Address",""),IF($AQ12="","Current Stage",""),IF($AF12="","Next Action",""),IF($AG12="","Next Action Due Date",""),IF($AH12="","Assigned Owner",""),IF($H12="","REI BlackBook Link",""))) | AX12: =IF($C12="","",IF(COUNTIFS($C$2:$C$1000,$C12,$AQ$2:$AQ$1000,"<>Lost / Closed Out")>1,"Duplicate","")) | AY12: =IF($B12="","",IF($AQ12="Verbal Agreement",100,IF($AQ12="Contract Sent",95,IF($AQ12="Active Negotiation",85,IF($AQ12="Offer Sent",70,IF($AQ12="Offer Preparation",60,IF($AQ12="Visit Completed — Needs Review",50,IF($AQ12="Visit Scheduled",30,IF($AQ12="Long-Term Nurture",10,IF($AQ12="Contract Signed",5,0)))))))))+IF($AK12="",0,MIN($AK12,20))+IF($AL12="Yes",5,0)) | AZ12: 46221 | BA12: 46224 | BB12: Cherry | BC12: TEST | BD12: =IF($B12="","",IF($BE12<>"","Exception",IF($AW12<>"","Incomplete","OK"))) | BE12: =IF($B12="","",_xlfn.TEXTJOIN(" | ",TRUE,IF(AND($K12="Completed",$M12=""),"Completed visit missing Visit Notes",""),IF(AND($K12="Completed",$S12=""),"Completed visit missing Seller Motivation (or add Exception note)",""),IF(AND($AQ12="Offer Sent",OR($X12="",$AA12="")),"Offer Sent needs Approved Offer Amount + Offer Sent Date",""),IF(AND($AQ12="Active Negotiation",OR($AE12="",$AF12="",$AH12="",$AG12="")),"Active Negotiation needs Last Contact Result + Next Action + Owner + Due Date",""),IF(AND($AQ12="Contract Sent",$AT12="",$R12=""),"Contract Sent needs Contract Sent Date or File Link",""),IF(AND($AQ12="Contract Signed",$AU12=""),"Contract Signed needs Contract Signed Date",""),IF(AND($AQ12="Long-Term Nurture",OR($AG12="",$AG12<=TODAY())),"Long-Term Nurture needs an exact FUTURE follow-up date",""),IF(AND($AQ12="Lost / Closed Out",OR($AR12="",$AS12="")),"Lost / Closed Out needs Final Disposition + Closeout Reason",""),IF(AND($AM12="Sent",$AO12=""),"Gift marked Sent without recorded approval",""),IF($AX12="Duplicate","Duplicate active record for this address",""))) | BF12: Yes
A13: TEST-02 | B13: 200 Test Contract Sent Ave, Testville, CA 90002 | C13: =IF($B13="","",TRIM(LOWER(SUBSTITUTE(SUBSTITUTE(SUBSTITUTE(SUBSTITUTE(SUBSTITUTE($B13,",",""),".","")," apt "," "),"#","")," unit "," ")))) | D13: Sam Sent | E13: (000) 000-0002 | G13: TV | H13: https://app.reiblackbook.com/lead/test02 | I13: 46218 | K13: Completed | L13: Juan | M13: Clean title; ready to move. | R13: https://drive.google.com/test02-contract | S13: Downsizing — motivated | X13: 720000 | Y13: Accepted | AA13: 46219 | AD13: 46224 | AE13: Seller reviewing contract | AF13: Confirm signature | AG13: 46225 | AH13: Cherry | AJ13: =IF($B13="","",IF(AND($AD13="",$BA13="",$I13=""),"",TODAY()-MAX($AD13,$BA13,$I13))) | AK13: =IF($B13="","",IF($AG13="","",IF(TODAY()>$AG13,TODAY()-$AG13,0))) | AL13: =IF($B13="","",IF(OR($AQ13="Lost / Closed Out",$AQ13="Long-Term Nurture",$AQ13="Contract Signed"),"No",IF(MAX($AD13,$BA13,$I13)=0,"No",IF(NETWORKDAYS(MAX($AD13,$BA13,$I13),TODAY())-1>=3,"Yes","No")))) | AQ13: Contract Sent | AT13: 46223 | AW13: =IF(OR($B13="",$AQ13="Lost / Closed Out"),"",_xlfn.TEXTJOIN(", ",TRUE,IF($B13="","Property Address",""),IF($AQ13="","Current Stage",""),IF($AF13="","Next Action",""),IF($AG13="","Next Action Due Date",""),IF($AH13="","Assigned Owner",""),IF($H13="","REI BlackBook Link",""))) | AX13: =IF($C13="","",IF(COUNTIFS($C$2:$C$1000,$C13,$AQ$2:$AQ$1000,"<>Lost / Closed Out")>1,"Duplicate","")) | AY13: =IF($B13="","",IF($AQ13="Verbal Agreement",100,IF($AQ13="Contract Sent",95,IF($AQ13="Active Negotiation",85,IF($AQ13="Offer Sent",70,IF($AQ13="Offer Preparation",60,IF($AQ13="Visit Completed — Needs Review",50,IF($AQ13="Visit Scheduled",30,IF($AQ13="Long-Term Nurture",10,IF($AQ13="Contract Signed",5,0)))))))))+IF($AK13="",0,MIN($AK13,20))+IF($AL13="Yes",5,0)) | AZ13: 46218 | BA13: 46224 | BB13: Cherry | BC13: TEST | BD13: =IF($B13="","",IF($BE13<>"","Exception",IF($AW13<>"","Incomplete","OK"))) | BE13: =IF($B13="","",_xlfn.TEXTJOIN(" | ",TRUE,IF(AND($K13="Completed",$M13=""),"Completed visit missing Visit Notes",""),IF(AND($K13="Completed",$S13=""),"Completed visit missing Seller Motivation (or add Exception note)",""),IF(AND($AQ13="Offer Sent",OR($X13="",$AA13="")),"Offer Sent needs Approved Offer Amount + Offer Sent Date",""),IF(AND($AQ13="Active Negotiation",OR($AE13="",$AF13="",$AH13="",$AG13="")),"Active Negotiation needs Last Contact Result + Next Action + Owner + Due Date",""),IF(AND($AQ13="Contract Sent",$AT13="",$R13=""),"Contract Sent needs Contract Sent Date or File Link",""),IF(AND($AQ13="Contract Signed",$AU13=""),"Contract Signed needs Contract Signed Date",""),IF(AND($AQ13="Long-Term Nurture",OR($AG13="",$AG13<=TODAY())),"Long-Term Nurture needs an exact FUTURE follow-up date",""),IF(AND($AQ13="Lost / Closed Out",OR($AR13="",$AS13="")),"Lost / Closed Out needs Final Disposition + Closeout Reason",""),IF(AND($AM13="Sent",$AO13=""),"Gift marked Sent without recorded approval",""),IF($AX13="Duplicate","Duplicate active record for this address",""))) | BF13: Yes
A14: TEST-03 | B14: 300 Test Signed Blvd, Testville, CA 90003 | C14: =IF($B14="","",TRIM(LOWER(SUBSTITUTE(SUBSTITUTE(SUBSTITUTE(SUBSTITUTE(SUBSTITUTE($B14,",",""),".","")," apt "," "),"#","")," unit "," ")))) | D14: Sid Signed | E14: (000) 000-0003 | G14: Direct Mail | H14: https://app.reiblackbook.com/lead/test03 | I14: 46213 | K14: Completed | L14: Juan | M14: Signed. | S14: Estate sale — motivated | X14: 555000 | Y14: Accepted | AA14: 46214 | AD14: 46221 | AE14: Contract signed | AF14: Hand off signed contract to JM | AG14: 46223 | AH14: JM | AJ14: =IF($B14="","",IF(AND($AD14="",$BA14="",$I14=""),"",TODAY()-MAX($AD14,$BA14,$I14))) | AK14: =IF($B14="","",IF($AG14="","",IF(TODAY()>$AG14,TODAY()-$AG14,0))) | AL14: =IF($B14="","",IF(OR($AQ14="Lost / Closed Out",$AQ14="Long-Term Nurture",$AQ14="Contract Signed"),"No",IF(MAX($AD14,$BA14,$I14)=0,"No",IF(NETWORKDAYS(MAX($AD14,$BA14,$I14),TODAY())-1>=3,"Yes","No")))) | AQ14: Contract Signed | AR14: Contracted | AT14: 46217 | AU14: 46221 | AV14: Ready for Handoff | AW14: =IF(OR($B14="",$AQ14="Lost / Closed Out"),"",_xlfn.TEXTJOIN(", ",TRUE,IF($B14="","Property Address",""),IF($AQ14="","Current Stage",""),IF($AF14="","Next Action",""),IF($AG14="","Next Action Due Date",""),IF($AH14="","Assigned Owner",""),IF($H14="","REI BlackBook Link",""))) | AX14: =IF($C14="","",IF(COUNTIFS($C$2:$C$1000,$C14,$AQ$2:$AQ$1000,"<>Lost / Closed Out")>1,"Duplicate","")) | AY14: =IF($B14="","",IF($AQ14="Verbal Agreement",100,IF($AQ14="Contract Sent",95,IF($AQ14="Active Negotiation",85,IF($AQ14="Offer Sent",70,IF($AQ14="Offer Preparation",60,IF($AQ14="Visit Completed — Needs Review",50,IF($AQ14="Visit Scheduled",30,IF($AQ14="Long-Term Nurture",10,IF($AQ14="Contract Signed",5,0)))))))))+IF($AK14="",0,MIN($AK14,20))+IF($AL14="Yes",5,0)) | AZ14: 46213 | BA14: 46221 | BB14: Cherry | BC14: TEST | BD14: =IF($B14="","",IF($BE14<>"","Exception",IF($AW14<>"","Incomplete","OK"))) | BE14: =IF($B14="","",_xlfn.TEXTJOIN(" | ",TRUE,IF(AND($K14="Completed",$M14=""),"Completed visit missing Visit Notes",""),IF(AND($K14="Completed",$S14=""),"Completed visit missing Seller Motivation (or add Exception note)",""),IF(AND($AQ14="Offer Sent",OR($X14="",$AA14="")),"Offer Sent needs Approved Offer Amount + Offer Sent Date",""),IF(AND($AQ14="Active Negotiation",OR($AE14="",$AF14="",$AH14="",$AG14="")),"Active Negotiation needs Last Contact Result + Next Action + Owner + Due Date",""),IF(AND($AQ14="Contract Sent",$AT14="",$R14=""),"Contract Sent needs Contract Sent Date or File Link",""),IF(AND($AQ14="Contract Signed",$AU14=""),"Contract Signed needs Contract Signed Date",""),IF(AND($AQ14="Long-Term Nurture",OR($AG14="",$AG14<=TODAY())),"Long-Term Nurture needs an exact FUTURE follow-up date",""),IF(AND($AQ14="Lost / Closed Out",OR($AR14="",$AS14="")),"Lost / Closed Out needs Final Disposition + Closeout Reason",""),IF(AND($AM14="Sent",$AO14=""),"Gift marked Sent without recorded approval",""),IF($AX14="Duplicate","Duplicate active record for this address",""))) | BF14: Yes
A15: TEST-04 | B15: 400 Test Needs Review St, Testville, CA 90004 | C15: =IF($B15="","",TRIM(LOWER(SUBSTITUTE(SUBSTITUTE(SUBSTITUTE(SUBSTITUTE(SUBSTITUTE($B15,",",""),".","")," apt "," "),"#","")," unit "," ")))) | D15: Nia Needs-Review | E15: (000) 000-0004 | G15: PPC | H15: https://app.reiblackbook.com/lead/test04 | I15: 46224 | K15: Completed | L15: Juan | M15: Visit done; needs offer/pass decision. | S15: Job relocation | AD15: 46224 | AE15: Walkthrough complete | AF15: Decide: make offer or pass | AG15: 46224 | AH15: Jonathan | AJ15: =IF($B15="","",IF(AND($AD15="",$BA15="",$I15=""),"",TODAY()-MAX($AD15,$BA15,$I15))) | AK15: =IF($B15="","",IF($AG15="","",IF(TODAY()>$AG15,TODAY()-$AG15,0))) | AL15: =IF($B15="","",IF(OR($AQ15="Lost / Closed Out",$AQ15="Long-Term Nurture",$AQ15="Contract Signed"),"No",IF(MAX($AD15,$BA15,$I15)=0,"No",IF(NETWORKDAYS(MAX($AD15,$BA15,$I15),TODAY())-1>=3,"Yes","No")))) | AQ15: Visit Completed — Needs Review | AW15: =IF(OR($B15="",$AQ15="Lost / Closed Out"),"",_xlfn.TEXTJOIN(", ",TRUE,IF($B15="","Property Address",""),IF($AQ15="","Current Stage",""),IF($AF15="","Next Action",""),IF($AG15="","Next Action Due Date",""),IF($AH15="","Assigned Owner",""),IF($H15="","REI BlackBook Link",""))) | AX15: =IF($C15="","",IF(COUNTIFS($C$2:$C$1000,$C15,$AQ$2:$AQ$1000,"<>Lost / Closed Out")>1,"Duplicate","")) | AY15: =IF($B15="","",IF($AQ15="Verbal Agreement",100,IF($AQ15="Contract Sent",95,IF($AQ15="Active Negotiation",85,IF($AQ15="Offer Sent",70,IF($AQ15="Offer Preparation",60,IF($AQ15="Visit Completed — Needs Review",50,IF($AQ15="Visit Scheduled",30,IF($AQ15="Long-Term Nurture",10,IF($AQ15="Contract Signed",5,0)))))))))+IF($AK15="",0,MIN($AK15,20))+IF($AL15="Yes",5,0)) | AZ15: 46224 | BA15: 46224 | BB15: Jonathan | BC15: TEST | BD15: =IF($B15="","",IF($BE15<>"","Exception",IF($AW15<>"","Incomplete","OK"))) | BE15: =IF($B15="","",_xlfn.TEXTJOIN(" | ",TRUE,IF(AND($K15="Completed",$M15=""),"Completed visit missing Visit Notes",""),IF(AND($K15="Completed",$S15=""),"Completed visit missing Seller Motivation (or add Exception note)",""),IF(AND($AQ15="Offer Sent",OR($X15="",$AA15="")),"Offer Sent needs Approved Offer Amount + Offer Sent Date",""),IF(AND($AQ15="Active Negotiation",OR($AE15="",$AF15="",$AH15="",$AG15="")),"Active Negotiation needs Last Contact Result + Next Action + Owner + Due Date",""),IF(AND($AQ15="Contract Sent",$AT15="",$R15=""),"Contract Sent needs Contract Sent Date or File Link",""),IF(AND($AQ15="Contract Signed",$AU15=""),"Contract Signed needs Contract Signed Date",""),IF(AND($AQ15="Long-Term Nurture",OR($AG15="",$AG15<=TODAY())),"Long-Term Nurture needs an exact FUTURE follow-up date",""),IF(AND($AQ15="Lost / Closed Out",OR($AR15="",$AS15="")),"Lost / Closed Out needs Final Disposition + Closeout Reason",""),IF(AND($AM15="Sent",$AO15=""),"Gift marked Sent without recorded approval",""),IF($AX15="Duplicate","Duplicate active record for this address",""))) | BF15: Yes
A16: TEST-05 | B16: 500 Test Nurture Way, Testville, CA 90005 | C16: =IF($B16="","",TRIM(LOWER(SUBSTITUTE(SUBSTITUTE(SUBSTITUTE(SUBSTITUTE(SUBSTITUTE($B16,",",""),".","")," apt "," "),"#","")," unit "," ")))) | D16: Nora Nurture | E16: (000) 000-0005 | G16: SEO | H16: https://app.reiblackbook.com/lead/test05 | I16: 46193 | K16: Completed | L16: Juan | M16: Not ready yet; call back in ~60 days. | S16: Will sell later this year | AD16: 46193 | AE16: Asked for callback in 60 days | AF16: Nurture check-in call | AG16: 46285 | AH16: Cherry | AJ16: =IF($B16="","",IF(AND($AD16="",$BA16="",$I16=""),"",TODAY()-MAX($AD16,$BA16,$I16))) | AK16: =IF($B16="","",IF($AG16="","",IF(TODAY()>$AG16,TODAY()-$AG16,0))) | AL16: =IF($B16="","",IF(OR($AQ16="Lost / Closed Out",$AQ16="Long-Term Nurture",$AQ16="Contract Signed"),"No",IF(MAX($AD16,$BA16,$I16)=0,"No",IF(NETWORKDAYS(MAX($AD16,$BA16,$I16),TODAY())-1>=3,"Yes","No")))) | AM16: Recommended | AN16: Strong rapport; long-term seller | AQ16: Long-Term Nurture | AW16: =IF(OR($B16="",$AQ16="Lost / Closed Out"),"",_xlfn.TEXTJOIN(", ",TRUE,IF($B16="","Property Address",""),IF($AQ16="","Current Stage",""),IF($AF16="","Next Action",""),IF($AG16="","Next Action Due Date",""),IF($AH16="","Assigned Owner",""),IF($H16="","REI BlackBook Link",""))) | AX16: =IF($C16="","",IF(COUNTIFS($C$2:$C$1000,$C16,$AQ$2:$AQ$1000,"<>Lost / Closed Out")>1,"Duplicate","")) | AY16: =IF($B16="","",IF($AQ16="Verbal Agreement",100,IF($AQ16="Contract Sent",95,IF($AQ16="Active Negotiation",85,IF($AQ16="Offer Sent",70,IF($AQ16="Offer Preparation",60,IF($AQ16="Visit Completed — Needs Review",50,IF($AQ16="Visit Scheduled",30,IF($AQ16="Long-Term Nurture",10,IF($AQ16="Contract Signed",5,0)))))))))+IF($AK16="",0,MIN($AK16,20))+IF($AL16="Yes",5,0)) | AZ16: 46193 | BA16: 46193 | BB16: Cherry | BC16: TEST | BD16: =IF($B16="","",IF($BE16<>"","Exception",IF($AW16<>"","Incomplete","OK"))) | BE16: =IF($B16="","",_xlfn.TEXTJOIN(" | ",TRUE,IF(AND($K16="Completed",$M16=""),"Completed visit missing Visit Notes",""),IF(AND($K16="Completed",$S16=""),"Completed visit missing Seller Motivation (or add Exception note)",""),IF(AND($AQ16="Offer Sent",OR($X16="",$AA16="")),"Offer Sent needs Approved Offer Amount + Offer Sent Date",""),IF(AND($AQ16="Active Negotiation",OR($AE16="",$AF16="",$AH16="",$AG16="")),"Active Negotiation needs Last Contact Result + Next Action + Owner + Due Date",""),IF(AND($AQ16="Contract Sent",$AT16="",$R16=""),"Contract Sent needs Contract Sent Date or File Link",""),IF(AND($AQ16="Contract Signed",$AU16=""),"Contract Signed needs Contract Signed Date",""),IF(AND($AQ16="Long-Term Nurture",OR($AG16="",$AG16<=TODAY())),"Long-Term Nurture needs an exact FUTURE follow-up date",""),IF(AND($AQ16="Lost / Closed Out",OR($AR16="",$AS16="")),"Lost / Closed Out needs Final Disposition + Closeout Reason",""),IF(AND($AM16="Sent",$AO16=""),"Gift marked Sent without recorded approval",""),IF($AX16="Duplicate","Duplicate active record for this address",""))) | BF16: Yes
A17: TEST-06 | B17: 600 Test Stalled Ct, Testville, CA 90006 | C17: =IF($B17="","",TRIM(LOWER(SUBSTITUTE(SUBSTITUTE(SUBSTITUTE(SUBSTITUTE(SUBSTITUTE($B17,",",""),".","")," apt "," "),"#","")," unit "," ")))) | D17: Stan Stalled | E17: (000) 000-0006 | G17: PPC | H17: https://app.reiblackbook.com/lead/test06 | I17: 46204 | K17: Completed | L17: Juan | M17: Offer sent; seller gone quiet. | S17: Was motivated; now unresponsive | X17: 500000 | Y17: Sent | AA17: 46205 | AD17: 46205 | AE17: Offer sent; no reply since | AF17: Re-attempt contact | AG17: 46211 | AH17: Juan | AI17: Seller Unresponsive | AJ17: =IF($B17="","",IF(AND($AD17="",$BA17="",$I17=""),"",TODAY()-MAX($AD17,$BA17,$I17))) | AK17: =IF($B17="","",IF($AG17="","",IF(TODAY()>$AG17,TODAY()-$AG17,0))) | AL17: =IF($B17="","",IF(OR($AQ17="Lost / Closed Out",$AQ17="Long-Term Nurture",$AQ17="Contract Signed"),"No",IF(MAX($AD17,$BA17,$I17)=0,"No",IF(NETWORKDAYS(MAX($AD17,$BA17,$I17),TODAY())-1>=3,"Yes","No")))) | AQ17: Offer Sent | AW17: =IF(OR($B17="",$AQ17="Lost / Closed Out"),"",_xlfn.TEXTJOIN(", ",TRUE,IF($B17="","Property Address",""),IF($AQ17="","Current Stage",""),IF($AF17="","Next Action",""),IF($AG17="","Next Action Due Date",""),IF($AH17="","Assigned Owner",""),IF($H17="","REI BlackBook Link",""))) | AX17: =IF($C17="","",IF(COUNTIFS($C$2:$C$1000,$C17,$AQ$2:$AQ$1000,"<>Lost / Closed Out")>1,"Duplicate","")) | AY17: =IF($B17="","",IF($AQ17="Verbal Agreement",100,IF($AQ17="Contract Sent",95,IF($AQ17="Active Negotiation",85,IF($AQ17="Offer Sent",70,IF($AQ17="Offer Preparation",60,IF($AQ17="Visit Completed — Needs Review",50,IF($AQ17="Visit Scheduled",30,IF($AQ17="Long-Term Nurture",10,IF($AQ17="Contract Signed",5,0)))))))))+IF($AK17="",0,MIN($AK17,20))+IF($AL17="Yes",5,0)) | AZ17: 46204 | BA17: 46205 | BB17: Juan | BC17: TEST | BD17: =IF($B17="","",IF($BE17<>"","Exception",IF($AW17<>"","Incomplete","OK"))) | BE17: =IF($B17="","",_xlfn.TEXTJOIN(" | ",TRUE,IF(AND($K17="Completed",$M17=""),"Completed visit missing Visit Notes",""),IF(AND($K17="Completed",$S17=""),"Completed visit missing Seller Motivation (or add Exception note)",""),IF(AND($AQ17="Offer Sent",OR($X17="",$AA17="")),"Offer Sent needs Approved Offer Amount + Offer Sent Date",""),IF(AND($AQ17="Active Negotiation",OR($AE17="",$AF17="",$AH17="",$AG17="")),"Active Negotiation needs Last Contact Result + Next Action + Owner + Due Date",""),IF(AND($AQ17="Contract Sent",$AT17="",$R17=""),"Contract Sent needs Contract Sent Date or File Link",""),IF(AND($AQ17="Contract Signed",$AU17=""),"Contract Signed needs Contract Signed Date",""),IF(AND($AQ17="Long-Term Nurture",OR($AG17="",$AG17<=TODAY())),"Long-Term Nurture needs an exact FUTURE follow-up date",""),IF(AND($AQ17="Lost / Closed Out",OR($AR17="",$AS17="")),"Lost / Closed Out needs Final Disposition + Closeout Reason",""),IF(AND($AM17="Sent",$AO17=""),"Gift marked Sent without recorded approval",""),IF($AX17="Duplicate","Duplicate active record for this address",""))) | BF17: Yes
A18: TEST-07 | B18: 700 Test Negotiation Rd, Testville, CA 90007 | C18: =IF($B18="","",TRIM(LOWER(SUBSTITUTE(SUBSTITUTE(SUBSTITUTE(SUBSTITUTE(SUBSTITUTE($B18,",",""),".","")," apt "," "),"#","")," unit "," ")))) | D18: Neil Negotiate | E18: (000) 000-0007 | G18: TV | H18: https://app.reiblackbook.com/lead/test07 | I18: 46219 | K18: Completed | L18: Juan | M18: Seller countered. | S18: Motivated but wants more money | X18: 610000 | Y18: Countered | AA18: 46220 | AC18: 660000 | AD18: 46224 | AE18: Seller countered at $660k | AF18: Cherry/Juan decide counter response | AG18: 46225 | AH18: Cherry | AI18: Price | AJ18: =IF($B18="","",IF(AND($AD18="",$BA18="",$I18=""),"",TODAY()-MAX($AD18,$BA18,$I18))) | AK18: =IF($B18="","",IF($AG18="","",IF(TODAY()>$AG18,TODAY()-$AG18,0))) | AL18: =IF($B18="","",IF(OR($AQ18="Lost / Closed Out",$AQ18="Long-Term Nurture",$AQ18="Contract Signed"),"No",IF(MAX($AD18,$BA18,$I18)=0,"No",IF(NETWORKDAYS(MAX($AD18,$BA18,$I18),TODAY())-1>=3,"Yes","No")))) | AQ18: Active Negotiation | AW18: =IF(OR($B18="",$AQ18="Lost / Closed Out"),"",_xlfn.TEXTJOIN(", ",TRUE,IF($B18="","Property Address",""),IF($AQ18="","Current Stage",""),IF($AF18="","Next Action",""),IF($AG18="","Next Action Due Date",""),IF($AH18="","Assigned Owner",""),IF($H18="","REI BlackBook Link",""))) | AX18: =IF($C18="","",IF(COUNTIFS($C$2:$C$1000,$C18,$AQ$2:$AQ$1000,"<>Lost / Closed Out")>1,"Duplicate","")) | AY18: =IF($B18="","",IF($AQ18="Verbal Agreement",100,IF($AQ18="Contract Sent",95,IF($AQ18="Active Negotiation",85,IF($AQ18="Offer Sent",70,IF($AQ18="Offer Preparation",60,IF($AQ18="Visit Completed — Needs Review",50,IF($AQ18="Visit Scheduled",30,IF($AQ18="Long-Term Nurture",10,IF($AQ18="Contract Signed",5,0)))))))))+IF($AK18="",0,MIN($AK18,20))+IF($AL18="Yes",5,0)) | AZ18: 46219 | BA18: 46224 | BB18: Cherry | BC18: TEST | BD18: =IF($B18="","",IF($BE18<>"","Exception",IF($AW18<>"","Incomplete","OK"))) | BE18: =IF($B18="","",_xlfn.TEXTJOIN(" | ",TRUE,IF(AND($K18="Completed",$M18=""),"Completed visit missing Visit Notes",""),IF(AND($K18="Completed",$S18=""),"Completed visit missing Seller Motivation (or add Exception note)",""),IF(AND($AQ18="Offer Sent",OR($X18="",$AA18="")),"Offer Sent needs Approved Offer Amount + Offer Sent Date",""),IF(AND($AQ18="Active Negotiation",OR($AE18="",$AF18="",$AH18="",$AG18="")),"Active Negotiation needs Last Contact Result + Next Action + Owner + Due Date",""),IF(AND($AQ18="Contract Sent",$AT18="",$R18=""),"Contract Sent needs Contract Sent Date or File Link",""),IF(AND($AQ18="Contract Signed",$AU18=""),"Contract Signed needs Contract Signed Date",""),IF(AND($AQ18="Long-Term Nurture",OR($AG18="",$AG18<=TODAY())),"Long-Term Nurture needs an exact FUTURE follow-up date",""),IF(AND($AQ18="Lost / Closed Out",OR($AR18="",$AS18="")),"Lost / Closed Out needs Final Disposition + Closeout Reason",""),IF(AND($AM18="Sent",$AO18=""),"Gift marked Sent without recorded approval",""),IF($AX18="Duplicate","Duplicate active record for this address",""))) | BF18: Yes
A19: TEST-08 | B19: 700 Test Negotiation Rd., Testville, CA 90007 | C19: =IF($B19="","",TRIM(LOWER(SUBSTITUTE(SUBSTITUTE(SUBSTITUTE(SUBSTITUTE(SUBSTITUTE($B19,",",""),".","")," apt "," "),"#","")," unit "," ")))) | D19: Duplicate Entry | E19: (000) 000-0008 | G19: TV | H19: https://app.reiblackbook.com/lead/test08 | I19: 46219 | K19: Scheduled | L19: Juan | AF19: Verify duplicate | AG19: 46226 | AH19: Cherry | AJ19: =IF($B19="","",IF(AND($AD19="",$BA19="",$I19=""),"",TODAY()-MAX($AD19,$BA19,$I19))) | AK19: =IF($B19="","",IF($AG19="","",IF(TODAY()>$AG19,TODAY()-$AG19,0))) | AL19: =IF($B19="","",IF(OR($AQ19="Lost / Closed Out",$AQ19="Long-Term Nurture",$AQ19="Contract Signed"),"No",IF(MAX($AD19,$BA19,$I19)=0,"No",IF(NETWORKDAYS(MAX($AD19,$BA19,$I19),TODAY())-1>=3,"Yes","No")))) | AQ19: Visit Scheduled | AW19: =IF(OR($B19="",$AQ19="Lost / Closed Out"),"",_xlfn.TEXTJOIN(", ",TRUE,IF($B19="","Property Address",""),IF($AQ19="","Current Stage",""),IF($AF19="","Next Action",""),IF($AG19="","Next Action Due Date",""),IF($AH19="","Assigned Owner",""),IF($H19="","REI BlackBook Link",""))) | AX19: =IF($C19="","",IF(COUNTIFS($C$2:$C$1000,$C19,$AQ$2:$AQ$1000,"<>Lost / Closed Out")>1,"Duplicate","")) | AY19: =IF($B19="","",IF($AQ19="Verbal Agreement",100,IF($AQ19="Contract Sent",95,IF($AQ19="Active Negotiation",85,IF($AQ19="Offer Sent",70,IF($AQ19="Offer Preparation",60,IF($AQ19="Visit Completed — Needs Review",50,IF($AQ19="Visit Scheduled",30,IF($AQ19="Long-Term Nurture",10,IF($AQ19="Contract Signed",5,0)))))))))+IF($AK19="",0,MIN($AK19,20))+IF($AL19="Yes",5,0)) | AZ19: 46219 | BA19: 46219 | BB19: Cherry | BC19: TEST | BD19: =IF($B19="","",IF($BE19<>"","Exception",IF($AW19<>"","Incomplete","OK"))) | BE19: =IF($B19="","",_xlfn.TEXTJOIN(" | ",TRUE,IF(AND($K19="Completed",$M19=""),"Completed visit missing Visit Notes",""),IF(AND($K19="Completed",$S19=""),"Completed visit missing Seller Motivation (or add Exception note)",""),IF(AND($AQ19="Offer Sent",OR($X19="",$AA19="")),"Offer Sent needs Approved Offer Amount + Offer Sent Date",""),IF(AND($AQ19="Active Negotiation",OR($AE19="",$AF19="",$AH19="",$AG19="")),"Active Negotiation needs Last Contact Result + Next Action + Owner + Due Date",""),IF(AND($AQ19="Contract Sent",$AT19="",$R19=""),"Contract Sent needs Contract Sent Date or File Link",""),IF(AND($AQ19="Contract Signed",$AU19=""),"Contract Signed needs Contract Signed Date",""),IF(AND($AQ19="Long-Term Nurture",OR($AG19="",$AG19<=TODAY())),"Long-Term Nurture needs an exact FUTURE follow-up date",""),IF(AND($AQ19="Lost / Closed Out",OR($AR19="",$AS19="")),"Lost / Closed Out needs Final Disposition + Closeout Reason",""),IF(AND($AM19="Sent",$AO19=""),"Gift marked Sent without recorded approval",""),IF($AX19="Duplicate","Duplicate active record for this address",""))) | BF19: Yes
